[2025-07-22 11:45:39] [ERROR] Unexpected error while deleting volume
Traceback (most recent call last):
  File "C:\Users\stude\Desktop\Python\DockerManager\Backend\main.py", line 220, in delete_docker_volume
    raise HTTPException(
    ...<2 lines>...
    )
fastapi.exceptions.HTTPException: 400: Cannot delete volume 'test-volume-for-db': it is used by container 'redis'
[2025-07-22 11:46:07] [ERROR] Unexpected error while deleting volume
Traceback (most recent call last):
  File "C:\Users\stude\Desktop\Python\DockerManager\Backend\main.py", line 220, in delete_docker_volume
    raise HTTPException(
    ...<2 lines>...
    )
fastapi.exceptions.HTTPException: 400: Cannot delete volume 'test-volume-for-db': it is used by container 'redis'
[2025-07-22 11:46:40] [ERROR] Unexpected error while deleting volume
Traceback (most recent call last):
  File "C:\Users\stude\Desktop\Python\DockerManager\Backend\main.py", line 220, in delete_docker_volume
    raise HTTPException(
    ...<2 lines>...
    )
fastapi.exceptions.HTTPException: 400: Cannot delete volume 'test-volume-for-db': it is used by container 'redis'
[2025-07-22 11:50:26] [ERROR] Unexpected error while deleting volume 'test-volume-for-db'
Traceback (most recent call last):
  File "C:\Users\stude\Desktop\Python\DockerManager\Backend\main.py", line 217, in delete_docker_volume
    raise HTTPException(
    ...<2 lines>...
    )
fastapi.exceptions.HTTPException: 400: Cannot delete volume 'test-volume-for-db': in use by container 'redis'
[2025-07-22 11:57:40] [INFO] Creating volume 'test_volume'
[2025-07-22 12:43:01] [ERROR] Unexpected error while deleting container '2e43b5d05398'
Traceback (most recent call last):
  File "C:\Users\stude\Desktop\Python\DockerManager\Backend\main.py", line 206, in delete_container
    raise HTTPException(
    ...<2 lines>...
    )
fastapi.exceptions.HTTPException: 400: Container 'ubuntu_test' is running. Use `force=true` to remove it.
[2025-07-22 12:43:11] [INFO] Stats stream stopped for container 2e43b5d05398
